2022-09-06 20:56:20,070 ERROR: Exception on /auth/login [POST] [in C:\Users\User\PycharmProjects\flask_miniblog\env\lib\site-packages\flask\app.py:1454]
Traceback (most recent call last):
  File "C:\Users\User\PycharmProjects\flask_miniblog\env\lib\site-packages\sqlalchemy\engine\base.py", line 1770, in _execute_context
    self.dialect.do_execute(
  File "C:\Users\User\PycharmProjects\flask_miniblog\env\lib\site-packages\sqlalchemy\engine\default.py", line 717, in do_execute
    cursor.execute(statement, parameters)
sqlite3.OperationalError: no such column: user.last_message_read_time

The above exception was the direct cause of the following exception:

Traceback (most recent call last):
  File "C:\Users\User\PycharmProjects\flask_miniblog\env\lib\site-packages\flask\app.py", line 2070, in wsgi_app
    response = self.full_dispatch_request()
  File "C:\Users\User\PycharmProjects\flask_miniblog\env\lib\site-packages\flask\app.py", line 1515, in full_dispatch_request
    rv = self.handle_user_exception(e)
  File "C:\Users\User\PycharmProjects\flask_miniblog\env\lib\site-packages\flask\app.py", line 1513, in full_dispatch_request
    rv = self.dispatch_request()
  File "C:\Users\User\PycharmProjects\flask_miniblog\env\lib\site-packages\flask\app.py", line 1499, in dispatch_request
    return self.ensure_sync(self.view_functions[rule.endpoint])(**req.view_args)
  File "C:\Users\User\PycharmProjects\flask_miniblog\app\auth\routes.py", line 19, in login
    user = User.query.filter_by(username=form.username.data).first()
  File "C:\Users\User\PycharmProjects\flask_miniblog\env\lib\site-packages\sqlalchemy\orm\query.py", line 2760, in first
    return self.limit(1)._iter().first()
  File "C:\Users\User\PycharmProjects\flask_miniblog\env\lib\site-packages\sqlalchemy\orm\query.py", line 2844, in _iter
    result = self.session.execute(
  File "C:\Users\User\PycharmProjects\flask_miniblog\env\lib\site-packages\sqlalchemy\orm\session.py", line 1689, in execute
    result = conn._execute_20(statement, params or {}, execution_options)
  File "C:\Users\User\PycharmProjects\flask_miniblog\env\lib\site-packages\sqlalchemy\engine\base.py", line 1582, in _execute_20
    return meth(self, args_10style, kwargs_10style, execution_options)
  File "C:\Users\User\PycharmProjects\flask_miniblog\env\lib\site-packages\sqlalchemy\sql\elements.py", line 323, in _execute_on_connection
    return connection._execute_clauseelement(
  File "C:\Users\User\PycharmProjects\flask_miniblog\env\lib\site-packages\sqlalchemy\engine\base.py", line 1451, in _execute_clauseelement
    ret = self._execute_context(
  File "C:\Users\User\PycharmProjects\flask_miniblog\env\lib\site-packages\sqlalchemy\engine\base.py", line 1813, in _execute_context
    self._handle_dbapi_exception(
  File "C:\Users\User\PycharmProjects\flask_miniblog\env\lib\site-packages\sqlalchemy\engine\base.py", line 1994, in _handle_dbapi_exception
    util.raise_(
  File "C:\Users\User\PycharmProjects\flask_miniblog\env\lib\site-packages\sqlalchemy\util\compat.py", line 207, in raise_
    raise exception
  File "C:\Users\User\PycharmProjects\flask_miniblog\env\lib\site-packages\sqlalchemy\engine\base.py", line 1770, in _execute_context
    self.dialect.do_execute(
  File "C:\Users\User\PycharmProjects\flask_miniblog\env\lib\site-packages\sqlalchemy\engine\default.py", line 717, in do_execute
    cursor.execute(statement, parameters)
sqlalchemy.exc.OperationalError: (sqlite3.OperationalError) no such column: user.last_message_read_time
[SQL: SELECT user.id AS user_id, user.username AS user_username, user.email AS user_email, user.password_hash AS user_password_hash, user.about_me AS user_about_me, user.last_seen AS user_last_seen, user.last_message_read_time AS user_last_message_read_time 
FROM user 
WHERE user.username = ?
 LIMIT ? OFFSET ?]
[parameters: ('serg', 1, 0)]
(Background on this error at: http://sqlalche.me/e/14/e3q8)
2022-09-06 21:02:07,445 INFO: Microblog startup [in C:\Users\User\PycharmProjects\flask_miniblog\app\__init__.py:82]
2022-09-06 21:02:19,896 ERROR: Exception on /auth/login [POST] [in C:\Users\User\PycharmProjects\flask_miniblog\env\lib\site-packages\flask\app.py:1454]
Traceback (most recent call last):
  File "C:\Users\User\PycharmProjects\flask_miniblog\env\lib\site-packages\sqlalchemy\engine\base.py", line 1770, in _execute_context
    self.dialect.do_execute(
  File "C:\Users\User\PycharmProjects\flask_miniblog\env\lib\site-packages\sqlalchemy\engine\default.py", line 717, in do_execute
    cursor.execute(statement, parameters)
sqlite3.OperationalError: no such column: user.last_message_read_time

The above exception was the direct cause of the following exception:

Traceback (most recent call last):
  File "C:\Users\User\PycharmProjects\flask_miniblog\env\lib\site-packages\flask\app.py", line 2070, in wsgi_app
    response = self.full_dispatch_request()
  File "C:\Users\User\PycharmProjects\flask_miniblog\env\lib\site-packages\flask\app.py", line 1515, in full_dispatch_request
    rv = self.handle_user_exception(e)
  File "C:\Users\User\PycharmProjects\flask_miniblog\env\lib\site-packages\flask\app.py", line 1513, in full_dispatch_request
    rv = self.dispatch_request()
  File "C:\Users\User\PycharmProjects\flask_miniblog\env\lib\site-packages\flask\app.py", line 1499, in dispatch_request
    return self.ensure_sync(self.view_functions[rule.endpoint])(**req.view_args)
  File "C:\Users\User\PycharmProjects\flask_miniblog\app\auth\routes.py", line 19, in login
    user = User.query.filter_by(username=form.username.data).first()
  File "C:\Users\User\PycharmProjects\flask_miniblog\env\lib\site-packages\sqlalchemy\orm\query.py", line 2760, in first
    return self.limit(1)._iter().first()
  File "C:\Users\User\PycharmProjects\flask_miniblog\env\lib\site-packages\sqlalchemy\orm\query.py", line 2844, in _iter
    result = self.session.execute(
  File "C:\Users\User\PycharmProjects\flask_miniblog\env\lib\site-packages\sqlalchemy\orm\session.py", line 1689, in execute
    result = conn._execute_20(statement, params or {}, execution_options)
  File "C:\Users\User\PycharmProjects\flask_miniblog\env\lib\site-packages\sqlalchemy\engine\base.py", line 1582, in _execute_20
    return meth(self, args_10style, kwargs_10style, execution_options)
  File "C:\Users\User\PycharmProjects\flask_miniblog\env\lib\site-packages\sqlalchemy\sql\elements.py", line 323, in _execute_on_connection
    return connection._execute_clauseelement(
  File "C:\Users\User\PycharmProjects\flask_miniblog\env\lib\site-packages\sqlalchemy\engine\base.py", line 1451, in _execute_clauseelement
    ret = self._execute_context(
  File "C:\Users\User\PycharmProjects\flask_miniblog\env\lib\site-packages\sqlalchemy\engine\base.py", line 1813, in _execute_context
    self._handle_dbapi_exception(
  File "C:\Users\User\PycharmProjects\flask_miniblog\env\lib\site-packages\sqlalchemy\engine\base.py", line 1994, in _handle_dbapi_exception
    util.raise_(
  File "C:\Users\User\PycharmProjects\flask_miniblog\env\lib\site-packages\sqlalchemy\util\compat.py", line 207, in raise_
    raise exception
  File "C:\Users\User\PycharmProjects\flask_miniblog\env\lib\site-packages\sqlalchemy\engine\base.py", line 1770, in _execute_context
    self.dialect.do_execute(
  File "C:\Users\User\PycharmProjects\flask_miniblog\env\lib\site-packages\sqlalchemy\engine\default.py", line 717, in do_execute
    cursor.execute(statement, parameters)
sqlalchemy.exc.OperationalError: (sqlite3.OperationalError) no such column: user.last_message_read_time
[SQL: SELECT user.id AS user_id, user.username AS user_username, user.email AS user_email, user.password_hash AS user_password_hash, user.about_me AS user_about_me, user.last_seen AS user_last_seen, user.last_message_read_time AS user_last_message_read_time 
FROM user 
WHERE user.username = ?
 LIMIT ? OFFSET ?]
[parameters: ('serg', 1, 0)]
(Background on this error at: http://sqlalche.me/e/14/e3q8)
2022-09-06 21:03:09,720 INFO: Microblog startup [in C:\Users\User\PycharmProjects\flask_miniblog\app\__init__.py:82]
2022-09-06 21:03:29,945 INFO: Microblog startup [in C:\Users\User\PycharmProjects\flask_miniblog\app\__init__.py:82]
2022-09-06 21:03:50,645 INFO: Microblog startup [in C:\Users\User\PycharmProjects\flask_miniblog\app\__init__.py:82]
2022-09-06 21:06:27,615 INFO: Microblog startup [in C:\Users\User\PycharmProjects\flask_miniblog\app\__init__.py:82]
2022-09-06 22:02:12,965 INFO: Microblog startup [in C:\Users\User\PycharmProjects\flask_miniblog\app\__init__.py:82]
2022-09-06 22:02:23,205 INFO: Microblog startup [in C:\Users\User\PycharmProjects\flask_miniblog\app\__init__.py:82]
2022-09-06 22:02:42,315 INFO: Microblog startup [in C:\Users\User\PycharmProjects\flask_miniblog\app\__init__.py:82]
2022-09-06 22:02:55,055 INFO: Microblog startup [in C:\Users\User\PycharmProjects\flask_miniblog\app\__init__.py:82]
2022-09-06 22:03:20,360 INFO: Microblog startup [in C:\Users\User\PycharmProjects\flask_miniblog\app\__init__.py:82]
2022-09-07 19:30:42,499 INFO: Microblog startup [in C:\Users\User\PycharmProjects\flask_miniblog\app\__init__.py:82]
2022-09-07 19:32:11,733 INFO: Microblog startup [in C:\Users\User\PycharmProjects\flask_miniblog\app\__init__.py:82]
2022-09-07 19:33:20,333 INFO: Microblog startup [in C:\Users\User\PycharmProjects\flask_miniblog\app\__init__.py:82]
2022-09-07 19:35:56,518 INFO: Microblog startup [in C:\Users\User\PycharmProjects\flask_miniblog\app\__init__.py:82]
